<?xml version="1.0"?>
<robot name="mobile-robot">

    <material name="blue">
        <color rgba="0 0 0.8 1"/>
    </material>
    <material name="black">
        <color rgba="0 0 0 1"/>
    </material>
    <material name="white">
        <color rgba="1 1 1 1"/>
    </material>

<!--    <link name="base_footprint"/>-->
<!--    <joint name="footprint_to_base" type="fixed">-->
<!--        <origin xyz="0 0 0.085"/>-->
<!--        <parent link="base_footprint"/>-->
<!--        <child link="base_link"/>-->
<!--    </joint>-->

    <!-- 底盘 -->
    <link name="base_link">
        <visual>
            <geometry>
                <box size="0.43 0.29 0.1"/>
            </geometry>
            <material name="blue"/>
        </visual>
        <collision>
            <geometry>
                <box size="0.43 0.29 0.1"/>
            </geometry>
        </collision>
    </link>

    <!-- 左主动轮 -->
    <link name="left_driving_wheel">
        <visual>
            <geometry>
                <cylinder length="0.05" radius="0.065"/>
            </geometry>
            <origin xyz="0 0.025 0" rpy="1.57075 0 0"/>
            <material name="black"/>
        </visual>
        <collision>
            <geometry>
                <cylinder length="0.05" radius="0.065"/>
            </geometry>
            <origin xyz="0 0.025 0" rpy="1.57075 0 0"/>
        </collision>
    </link>
    <joint name="base_to_left_driving_wheel" type="continuous">
        <parent link="base_link"/>
        <child link="left_driving_wheel"/>
        <axis xyz="0 1 0"/>
        <origin xyz="0 0.145 -0.02"/>
    </joint>

    <!-- 右主动轮 -->
    <link name="right_driving_wheel">
        <visual>
            <geometry>
                <cylinder length="0.05" radius="0.065"/>
            </geometry>
            <origin xyz="0 -0.025 0" rpy="1.57075 0 0"/>
            <material name="black"/>
        </visual>
        <collision>
            <geometry>
                <cylinder length="0.05" radius="0.065"/>
            </geometry>
            <origin xyz="0 -0.025 0" rpy="1.57075 0 0"/>
        </collision>
    </link>
    <joint name="base_to_right_driving_wheel" type="continuous">
        <parent link="base_link"/>
        <child link="right_driving_wheel"/>
        <axis xyz="0 -1 0"/>
        <origin xyz="0 -0.145 -0.02"/>
    </joint>

    <!-- 左从动轮 -->
    <link name="left_driven_wheel">
        <visual>
            <geometry>
                <cylinder length="0.04" radius="0.05"/>
            </geometry>
            <origin xyz="0 0.02 0" rpy="1.57075 0 0"/>
            <material name="black"/>
        </visual>
        <collision>
            <geometry>
                <cylinder length="0.04" radius="0.05"/>
            </geometry>
            <origin xyz="0 0.02 0" rpy="1.57075 0 0"/>
        </collision>
    </link>
    <joint name="base_to_left_driven_wheel" type="fixed">
        <parent link="base_link"/>
        <child link="left_driven_wheel"/>
        <axis xyz="0 1 0"/>
        <origin xyz="0.16 0.145 -0.035"/>
    </joint>

    <!-- 右从动轮 -->
    <link name="right_driven_wheel">
        <visual>
            <geometry>
                <cylinder length="0.04" radius="0.05"/>
            </geometry>
            <origin xyz="0 -0.02 0" rpy="1.57075 0 0"/>
            <material name="black"/>
        </visual>
        <collision>
            <geometry>
                <cylinder length="0.04" radius="0.05"/>
            </geometry>
            <origin xyz="0 -0.02 0" rpy="1.57075 0 0"/>
        </collision>
    </link>
    <joint name="base_to_right_driven_wheel" type="fixed">
        <parent link="base_link"/>
        <child link="right_driven_wheel"/>
        <axis xyz="0 -1 0"/>
        <origin xyz="0.16 -0.145 -0.035"/>
    </joint>

    <!-- 左辅助轮 -->
    <link name="left_training_wheel">
        <visual>
            <geometry>
                <cylinder length="0.015" radius="0.0625"/>
            </geometry>
            <origin xyz="0 0.0075 0" rpy="1.57075 0 0"/>
            <material name="black"/>
        </visual>
        <collision>
            <geometry>
                <cylinder length="0.015" radius="0.0625"/>
            </geometry>
            <origin xyz="0 0.0075 0" rpy="1.57075 0 0"/>
        </collision>
    </link>
    <joint name="base_to_left_training_wheel" type="fixed">
        <parent link="base_link"/>
        <child link="left_training_wheel"/>
        <axis xyz="0 1 0"/>
        <origin xyz="-0.145 0.145 -0.02"/>
    </joint>

    <!-- 右辅助轮 -->
    <link name="right_training_wheel">
        <visual>
            <geometry>
                <cylinder length="0.015" radius="0.0625"/>
            </geometry>
            <origin xyz="0 -0.0075 0" rpy="1.57075 0 0"/>
            <material name="black"/>
        </visual>
        <collision>
            <geometry>
                <cylinder length="0.015" radius="0.0625"/>
            </geometry>
            <origin xyz="0 -0.0075 0" rpy="1.57075 0 0"/>
        </collision>
    </link>
    <joint name="base_to_right_training_wheel" type="fixed">
        <parent link="base_link"/>
        <child link="right_training_wheel"/>
        <axis xyz="0 -1 0"/>
        <origin xyz="-0.145 -0.145 -0.02"/>
    </joint>

<!--    &lt;!&ndash; 激光雷达 &ndash;&gt;-->
<!--    &lt;!&ndash; 汇博的程序会发布雷达tf变换，这里注释掉&ndash;&gt;-->
<!--    <link name="laser_frame">-->
<!--        <visual>-->
<!--            <geometry>-->
<!--                <cylinder length="0.04" radius="0.035"/>-->
<!--            </geometry>-->
<!--            <material name="white"/>-->
<!--        </visual>-->
<!--        <collision>-->
<!--            <geometry>-->
<!--                <cylinder length="0.04" radius="0.035"/>-->
<!--            </geometry>-->
<!--        </collision>-->
<!--    </link>-->
<!--    <joint name="base_to_lidar" type="fixed">-->
<!--        <parent link="base_link"/>-->
<!--        <child link="laser_frame"/>-->
<!--        <origin xyz="0.23 0 0.07" rpy="0 0 -1.55"/>-->
<!--    </joint>-->
</robot>